Workbook

Sheet Live Leaderboard
A1: CYDER CUP • LIVE LEADERBOARD
A3: Winning total | B3: =$B$4/2+0.5 -> 15.5
A4: Total points | B4: =SUM($C$15:$C$22)+SUMIFS($C$28:$C$55,$B$28:$B$55,"<>MATCH SUBTOTAL") -> 30
A6: TEAM NAVY | G6: CUP STATUS | I6: TEAM RED
A7: =SUM($H$15:$H$22)+SUMIFS($L$28:$L$55,$B$28:$B$55,"<>MATCH SUBTOTAL") -> 0 | G7: =IF(A7>=$B$3,"TEAM NAVY WINS",IF(I7>$B$3,"TEAM RED WINS",IF(A7>I7,"TEAM NAVY LEADS",IF(I7>A7,"TEAM RED LEADS","MATCH TIED")))) -> MATCH TIED | I7: =SUM($G$15:$G$22)+SUMIFS($K$28:$K$55,$B$28:$B$55,"<>MATCH SUBTOTAL") -> 0
G9: ="Points remaining: "&TEXT(MAX(0,$B$4-A7-I7),"0.0") -> Points remaining: 30.0
A10: ="Need "&TEXT(MAX(0,$B$3-A7),"0.0")&" more points to win" -> Need 15.5 more points to win | I10: ="Need "&TEXT(MAX(0,$B$3-I7),"0.0")&" more points to win" -> Need 15.5 more points to win
A13: ALL-TEAM EVENTS
A14: Event | B14: Segment | C14: Points | D14: Winner | E14: Result / Notes | F14: Status | G14: Red Pts | H14: Navy Pts | I14: Website Key
A15: Scramble | B15: Front 9 | C15: 1 | F15: =IF(D15="","Not Started","Final") -> Not Started | G15: =IF(D15="Red",C15,IF(D15="Tied",C15/2,0)) -> 0 | H15: =IF(D15="Navy",C15,IF(D15="Tied",C15/2,0)) -> 0 | I15: scramble-front-9
A16: Scramble | B16: Back 9 | C16: 1 | F16: =IF(D16="","Not Started","Final") -> Not Started | G16: =IF(D16="Red",C16,IF(D16="Tied",C16/2,0)) -> 0 | H16: =IF(D16="Navy",C16,IF(D16="Tied",C16/2,0)) -> 0 | I16: scramble-back-9
A17: Scramble | B17: Overall | C17: 1 | F17: =IF(D17="","Not Started","Final") -> Not Started | G17: =IF(D17="Red",C17,IF(D17="Tied",C17/2,0)) -> 0 | H17: =IF(D17="Navy",C17,IF(D17="Tied",C17/2,0)) -> 0 | I17: scramble-overall
A18: Drinking Games #1 | B18: Single event | C18: 1 | F18: =IF(D18="","Not Started","Final") -> Not Started | G18: =IF(D18="Red",C18,IF(D18="Tied",C18/2,0)) -> 0 | H18: =IF(D18="Navy",C18,IF(D18="Tied",C18/2,0)) -> 0 | I18: drinking-1
A19: Drinking Games #2 | B19: Single event | C19: 1 | F19: =IF(D19="","Not Started","Final") -> Not Started | G19: =IF(D19="Red",C19,IF(D19="Tied",C19/2,0)) -> 0 | H19: =IF(D19="Navy",C19,IF(D19="Tied",C19/2,0)) -> 0 | I19: drinking-2
A20: Drinking Games #3 | B20: Single event | C20: 1 | F20: =IF(D20="","Not Started","Final") -> Not Started | G20: =IF(D20="Red",C20,IF(D20="Tied",C20/2,0)) -> 0 | H20: =IF(D20="Navy",C20,IF(D20="Tied",C20/2,0)) -> 0 | I20: drinking-3
A21: Drinking Games #4 | B21: Single event | C21: 1 | F21: =IF(D21="","Not Started","Final") -> Not Started | G21: =IF(D21="Red",C21,IF(D21="Tied",C21/2,0)) -> 0 | H21: =IF(D21="Navy",C21,IF(D21="Tied",C21/2,0)) -> 0 | I21: drinking-4
A22: Drinking Games #5 | B22: Single event | C22: 1 | F22: =IF(D22="","Not Started","Final") -> Not Started | G22: =IF(D22="Red",C22,IF(D22="Tied",C22/2,0)) -> 0 | H22: =IF(D22="Navy",C22,IF(D22="Tied",C22/2,0)) -> 0 | I22: drinking-5
A25: SELECT-PLAYER EVENTS
A26: Event | B26: Segment | C26: Points | D26: Red Player 1 | E26: Red Player 2 | F26: Navy Player 1 | G26: Navy Player 2 | H26: Winner | I26: Result / Notes | J26: Status | K26: Red Pts | L26: Navy Pts | M26: Website Key
A27: Fourball #1 | B27: MATCH SUBTOTAL | C27: 3 | D27: Kevin Catliff | E27: Sam Griffiths | F27: JJ Meakings | G27: Eric Bleim | J27: =IF(COUNTA(H28:H30)=0,"Not Started",IF(COUNTA(H28:H30)<3,"In Progress","Final")) -> Not Started | K27: =SUM(K28:K30) -> 0 | L27: =SUM(L28:L30) -> 0 | M27: fourball-1
B28: Front 9 | C28: 1 | D28: =IF(D27="","",D27) -> Kevin Catliff | E28: =IF(E27="","",E27) -> Sam Griffiths | F28: =IF(F27="","",F27) -> JJ Meakings | G28: =IF(G27="","",G27) -> Eric Bleim | J28: =IF(H28="","Not Started","Final") -> Not Started | K28: =IF(H28="Red",C28,IF(H28="Tied",C28/2,0)) -> 0 | L28: =IF(H28="Navy",C28,IF(H28="Tied",C28/2,0)) -> 0 | M28: fourball-1-front-9
B29: Back 9 | C29: 1 | D29: =IF(D27="","",D27) -> Kevin Catliff | E29: =IF(E27="","",E27) -> Sam Griffiths | F29: =IF(F27="","",F27) -> JJ Meakings | G29: =IF(G27="","",G27) -> Eric Bleim | J29: =IF(H29="","Not Started","Final") -> Not Started | K29: =IF(H29="Red",C29,IF(H29="Tied",C29/2,0)) -> 0 | L29: =IF(H29="Navy",C29,IF(H29="Tied",C29/2,0)) -> 0 | M29: fourball-1-back-9
B30: Overall | C30: 1 | D30: =IF(D27="","",D27) -> Kevin Catliff | E30: =IF(E27="","",E27) -> Sam Griffiths | F30: =IF(F27="","",F27) -> JJ Meakings | G30: =IF(G27="","",G27) -> Eric Bleim | J30: =IF(H30="","Not Started","Final") -> Not Started | K30: =IF(H30="Red",C30,IF(H30="Tied",C30/2,0)) -> 0 | L30: =IF(H30="Navy",C30,IF(H30="Tied",C30/2,0)) -> 0 | M30: fourball-1-overall
A32: Fourball #2 | B32: MATCH SUBTOTAL | C32: 3 | D32: Sean Bromley | E32: Dylan Bradley | F32: Steve Wells | G32: George Collister | J32: =IF(COUNTA(H33:H35)=0,"Not Started",IF(COUNTA(H33:H35)<3,"In Progress","Final")) -> Not Started | K32: =SUM(K33:K35) -> 0 | L32: =SUM(L33:L35) -> 0 | M32: fourball-2
B33: Front 9 | C33: 1 | D33: =IF(D32="","",D32) -> Sean Bromley | E33: =IF(E32="","",E32) -> Dylan Bradley | F33: =IF(F32="","",F32) -> Steve Wells | G33: =IF(G32="","",G32) -> George Collister | J33: =IF(H33="","Not Started","Final") -> Not Started | K33: =IF(H33="Red",C33,IF(H33="Tied",C33/2,0)) -> 0 | L33: =IF(H33="Navy",C33,IF(H33="Tied",C33/2,0)) -> 0 | M33: fourball-2-front-9
B34: Back 9 | C34: 1 | D34: =IF(D32="","",D32) -> Sean Bromley | E34: =IF(E32="","",E32) -> Dylan Bradley | F34: =IF(F32="","",F32) -> Steve Wells | G34: =IF(G32="","",G32) -> George Collister | J34: =IF(H34="","Not Started","Final") -> Not Started | K34: =IF(H34="Red",C34,IF(H34="Tied",C34/2,0)) -> 0 | L34: =IF(H34="Navy",C34,IF(H34="Tied",C34/2,0)) -> 0 | M34: fourball-2-back-9
B35: Overall | C35: 1 | D35: =IF(D32="","",D32) -> Sean Bromley | E35: =IF(E32="","",E32) -> Dylan Bradley | F35: =IF(F32="","",F32) -> Steve Wells | G35: =IF(G32="","",G32) -> George Collister | J35: =IF(H35="","Not Started","Final") -> Not Started | K35: =IF(H35="Red",C35,IF(H35="Tied",C35/2,0)) -> 0 | L35: =IF(H35="Navy",C35,IF(H35="Tied",C35/2,0)) -> 0 | M35: fourball-2-overall
A37: Singles #1 | B37: MATCH SUBTOTAL | C37: 6 | D37: Sam Griffiths | F37: JJ Meakings | J37: =IF(COUNTA(H38:H40)=0,"Not Started",IF(COUNTA(H38:H40)<3,"In Progress","Final")) -> Not Started | K37: =SUM(K38:K40) -> 0 | L37: =SUM(L38:L40) -> 0 | M37: singles-1
B38: Front 9 | C38: 1 | D38: =IF(D37="","",D37) -> Sam Griffiths | F38: =IF(F37="","",F37) -> JJ Meakings | J38: =IF(H38="","Not Started","Final") -> Not Started | K38: =IF(H38="Red",C38,IF(H38="Tied",C38/2,0)) -> 0 | L38: =IF(H38="Navy",C38,IF(H38="Tied",C38/2,0)) -> 0 | M38: singles-1-front-9
B39: Back 9 | C39: 1 | D39: =IF(D37="","",D37) -> Sam Griffiths | F39: =IF(F37="","",F37) -> JJ Meakings | J39: =IF(H39="","Not Started","Final") -> Not Started | K39: =IF(H39="Red",C39,IF(H39="Tied",C39/2,0)) -> 0 | L39: =IF(H39="Navy",C39,IF(H39="Tied",C39/2,0)) -> 0 | M39: singles-1-back-9
B40: Overall | C40: 2 | D40: =IF(D37="","",D37) -> Sam Griffiths | F40: =IF(F37="","",F37) -> JJ Meakings | J40: =IF(H40="","Not Started","Final") -> Not Started | K40: =IF(H40="Red",C40,IF(H40="Tied",C40/2,0)) -> 0 | L40: =IF(H40="Navy",C40,IF(H40="Tied",C40/2,0)) -> 0 | M40: singles-1-overall
A42: Singles #2 | B42: MATCH SUBTOTAL | C42: 6 | D42: Kevin Catliff | F42: Steve Wells | J42: =IF(COUNTA(H43:H45)=0,"Not Started",IF(COUNTA(H43:H45)<3,"In Progress","Final")) -> Not Started | K42: =SUM(K43:K45) -> 0 | L42: =SUM(L43:L45) -> 0 | M42: singles-2
B43: Front 9 | C43: 1 | D43: =IF(D42="","",D42) -> Kevin Catliff | F43: =IF(F42="","",F42) -> Steve Wells | J43: =IF(H43="","Not Started","Final") -> Not Started | K43: =IF(H43="Red",C43,IF(H43="Tied",C43/2,0)) -> 0 | L43: =IF(H43="Navy",C43,IF(H43="Tied",C43/2,0)) -> 0 | M43: singles-2-front-9
B44: Back 9 | C44: 1 | D44: =IF(D42="","",D42) -> Kevin Catliff | F44: =IF(F42="","",F42) -> Steve Wells | J44: =IF(H44="","Not Started","Final") -> Not Started | K44: =IF(H44="Red",C44,IF(H44="Tied",C44/2,0)) -> 0 | L44: =IF(H44="Navy",C44,IF(H44="Tied",C44/2,0)) -> 0 | M44: singles-2-back-9
B45: Overall | C45: 2 | D45: =IF(D42="","",D42) -> Kevin Catliff | F45: =IF(F42="","",F42) -> Steve Wells | J45: =IF(H45="","Not Started","Final") -> Not Started | K45: =IF(H45="Red",C45,IF(H45="Tied",C45/2,0)) -> 0 | L45: =IF(H45="Navy",C45,IF(H45="Tied",C45/2,0)) -> 0 | M45: singles-2-overall
A47: Singles #3 | B47: MATCH SUBTOTAL | C47: 6 | D47: Sean Bromley | F47: George Collister | J47: =IF(COUNTA(H48:H50)=0,"Not Started",IF(COUNTA(H48:H50)<3,"In Progress","Final")) -> Not Started | K47: =SUM(K48:K50) -> 0 | L47: =SUM(L48:L50) -> 0 | M47: singles-3
B48: Front 9 | C48: 1 | D48: =IF(D47="","",D47) -> Sean Bromley | F48: =IF(F47="","",F47) -> George Collister | J48: =IF(H48="","Not Started","Final") -> Not Started | K48: =IF(H48="Red",C48,IF(H48="Tied",C48/2,0)) -> 0 | L48: =IF(H48="Navy",C48,IF(H48="Tied",C48/2,0)) -> 0 | M48: singles-3-front-9
B49: Back 9 | C49: 1 | D49: =IF(D47="","",D47) -> Sean Bromley | F49: =IF(F47="","",F47) -> George Collister | J49: =IF(H49="","Not Started","Final") -> Not Started | K49: =IF(H49="Red",C49,IF(H49="Tied",C49/2,0)) -> 0 | L49: =IF(H49="Navy",C49,IF(H49="Tied",C49/2,0)) -> 0 | M49: singles-3-back-9
B50: Overall | C50: 2 | D50: =IF(D47="","",D47) -> Sean Bromley | F50: =IF(F47="","",F47) -> George Collister | J50: =IF(H50="","Not Started","Final") -> Not Started | K50: =IF(H50="Red",C50,IF(H50="Tied",C50/2,0)) -> 0 | L50: =IF(H50="Navy",C50,IF(H50="Tied",C50/2,0)) -> 0 | M50: singles-3-overall
A52: Singles #4 | B52: MATCH SUBTOTAL | C52: 6 | D52: Dylan Bradley | F52: Eric Bleim | J52: =IF(COUNTA(H53:H55)=0,"Not Started",IF(COUNTA(H53:H55)<3,"In Progress","Final")) -> Not Started | K52: =SUM(K53:K55) -> 0 | L52: =SUM(L53:L55) -> 0 | M52: singles-4
...

Sheet Record Book
A1: CYDER CUP • RECORD BOOK
A3: Career history, annual champions, and player-level match results
A5: ANNUAL CUP RESULTS
A6: Year | B6: Champion | C6: Captain | D6: Final Score | E6: Red Pts | F6: Navy Pts
A7: 2019 | B7: Navy | C7: Eric Bleim | D7: 13.5 - 1.5 | E7: 1.5 | F7: 13.5
A8: 2020 | B8: Red | C8: Kevin Catliff | D8: 10 - 5 | E8: 10 | F8: 5
A9: 2021 | B9: Red | C9: Dylan Bradley | D9: 9 - 6 | E9: 9 | F9: 6
A10: 2022 | B10: Navy | C10: JJ Meakings | D10: 8 - 7 | E10: 7 | F10: 8
A11: 2025 | B11: Navy | C11: Eric Bleim | D11: 9.5 - 5.5 | E11: 5.5 | F11: 9.5
A14: ALL-TIME PLAYER RECORDS
A15: Player | B15: Team | C15: W | D15: L | E15: T | F15: Points %
A16: Steve Wells | B16: Navy | C16: =COUNTIFS(PlayerMatchHistory[Player],$A16,PlayerMatchHistory[Result],C$15)+COUNTIFS(PlayerMatchHistory[Player],"All",PlayerMatchHistory[Team],$B16,PlayerMatchHistory[Result],C$15) -> 10 | D16: =COUNTIFS(PlayerMatchHistory[Player],$A16,PlayerMatchHistory[Result],D$15)+COUNTIFS(PlayerMatchHistory[Player],"All",PlayerMatchHistory[Team],$B16,PlayerMatchHistory[Result],D$15) -> 5 | E16: =COUNTIFS(PlayerMatchHistory[Player],$A16,PlayerMatchHistory[Result],E$15)+COUNTIFS(PlayerMatchHistory[Player],"All",PlayerMatchHistory[Team],$B16,PlayerMatchHistory[Result],E$15) -> 0 | F16: =(C16+E16/2)/SUM(C16:E16) -> 0.66666667
A17: George Collister | B17: Navy | C17: =COUNTIFS(PlayerMatchHistory[Player],$A17,PlayerMatchHistory[Result],C$15)+COUNTIFS(PlayerMatchHistory[Player],"All",PlayerMatchHistory[Team],$B17,PlayerMatchHistory[Result],C$15) -> 9 | D17: =COUNTIFS(PlayerMatchHistory[Player],$A17,PlayerMatchHistory[Result],D$15)+COUNTIFS(PlayerMatchHistory[Player],"All",PlayerMatchHistory[Team],$B17,PlayerMatchHistory[Result],D$15) -> 6 | E17: =COUNTIFS(PlayerMatchHistory[Player],$A17,PlayerMatchHistory[Result],E$15)+COUNTIFS(PlayerMatchHistory[Player],"All",PlayerMatchHistory[Team],$B17,PlayerMatchHistory[Result],E$15) -> 0 | F17: =(C17+E17/2)/SUM(C17:E17) -> 0.6
A18: JJ Meakings | B18: Navy | C18: =COUNTIFS(PlayerMatchHistory[Player],$A18,PlayerMatchHistory[Result],C$15)+COUNTIFS(PlayerMatchHistory[Player],"All",PlayerMatchHistory[Team],$B18,PlayerMatchHistory[Result],C$15) -> 8 | D18: =COUNTIFS(PlayerMatchHistory[Player],$A18,PlayerMatchHistory[Result],D$15)+COUNTIFS(PlayerMatchHistory[Player],"All",PlayerMatchHistory[Team],$B18,PlayerMatchHistory[Result],D$15) -> 5 | E18: =COUNTIFS(PlayerMatchHistory[Player],$A18,PlayerMatchHistory[Result],E$15)+COUNTIFS(PlayerMatchHistory[Player],"All",PlayerMatchHistory[Team],$B18,PlayerMatchHistory[Result],E$15) -> 2 | F18: =(C18+E18/2)/SUM(C18:E18) -> 0.6
A19: Sam Griffiths | B19: Red | C19: =COUNTIFS(PlayerMatchHistory[Player],$A19,PlayerMatchHistory[Result],C$15)+COUNTIFS(PlayerMatchHistory[Player],"All",PlayerMatchHistory[Team],$B19,PlayerMatchHistory[Result],C$15) -> 8 | D19: =COUNTIFS(PlayerMatchHistory[Player],$A19,PlayerMatchHistory[Result],D$15)+COUNTIFS(PlayerMatchHistory[Player],"All",PlayerMatchHistory[Team],$B19,PlayerMatchHistory[Result],D$15) -> 6 | E19: =COUNTIFS(PlayerMatchHistory[Player],$A19,PlayerMatchHistory[Result],E$15)+COUNTIFS(PlayerMatchHistory[Player],"All",PlayerMatchHistory[Team],$B19,PlayerMatchHistory[Result],E$15) -> 1 | F19: =(C19+E19/2)/SUM(C19:E19) -> 0.56666667
A20: Eric Bleim | B20: Navy | C20: =COUNTIFS(PlayerMatchHistory[Player],$A20,PlayerMatchHistory[Result],C$15)+COUNTIFS(PlayerMatchHistory[Player],"All",PlayerMatchHistory[Team],$B20,PlayerMatchHistory[Result],C$15) -> 8 | D20: =COUNTIFS(PlayerMatchHistory[Player],$A20,PlayerMatchHistory[Result],D$15)+COUNTIFS(PlayerMatchHistory[Player],"All",PlayerMatchHistory[Team],$B20,PlayerMatchHistory[Result],D$15) -> 7 | E20: =COUNTIFS(PlayerMatchHistory[Player],$A20,PlayerMatchHistory[Result],E$15)+COUNTIFS(PlayerMatchHistory[Player],"All",PlayerMatchHistory[Team],$B20,PlayerMatchHistory[Result],E$15) -> 0 | F20: =(C20+E20/2)/SUM(C20:E20) -> 0.53333333
A21: Kevin Catliff | B21: Red | C21: =COUNTIFS(PlayerMatchHistory[Player],$A21,PlayerMatchHistory[Result],C$15)+COUNTIFS(PlayerMatchHistory[Player],"All",PlayerMatchHistory[Team],$B21,PlayerMatchHistory[Result],C$15) -> 6 | D21: =COUNTIFS(PlayerMatchHistory[Player],$A21,PlayerMatchHistory[Result],D$15)+COUNTIFS(PlayerMatchHistory[Player],"All",PlayerMatchHistory[Team],$B21,PlayerMatchHistory[Result],D$15) -> 8 | E21: =COUNTIFS(PlayerMatchHistory[Player],$A21,PlayerMatchHistory[Result],E$15)+COUNTIFS(PlayerMatchHistory[Player],"All",PlayerMatchHistory[Team],$B21,PlayerMatchHistory[Result],E$15) -> 1 | F21: =(C21+E21/2)/SUM(C21:E21) -> 0.43333333
A22: Sean Bromley | B22: Red | C22: =COUNTIFS(PlayerMatchHistory[Player],$A22,PlayerMatchHistory[Result],C$15)+COUNTIFS(PlayerMatchHistory[Player],"All",PlayerMatchHistory[Team],$B22,PlayerMatchHistory[Result],C$15) -> 5 | D22: =COUNTIFS(PlayerMatchHistory[Player],$A22,PlayerMatchHistory[Result],D$15)+COUNTIFS(PlayerMatchHistory[Player],"All",PlayerMatchHistory[Team],$B22,PlayerMatchHistory[Result],D$15) -> 10 | E22: =COUNTIFS(PlayerMatchHistory[Player],$A22,PlayerMatchHistory[Result],E$15)+COUNTIFS(PlayerMatchHistory[Player],"All",PlayerMatchHistory[Team],$B22,PlayerMatchHistory[Result],E$15) -> 0 | F22: =(C22+E22/2)/SUM(C22:E22) -> 0.33333333
A23: Dylan Bradley | B23: Red | C23: =COUNTIFS(PlayerMatchHistory[Player],$A23,PlayerMatchHistory[Result],C$15)+COUNTIFS(PlayerMatchHistory[Player],"All",PlayerMatchHistory[Team],$B23,PlayerMatchHistory[Result],C$15) -> 4 | D23: =COUNTIFS(PlayerMatchHistory[Player],$A23,PlayerMatchHistory[Result],D$15)+COUNTIFS(PlayerMatchHistory[Player],"All",PlayerMatchHistory[Team],$B23,PlayerMatchHistory[Result],D$15) -> 11 | E23: =COUNTIFS(PlayerMatchHistory[Player],$A23,PlayerMatchHistory[Result],E$15)+COUNTIFS(PlayerMatchHistory[Player],"All",PlayerMatchHistory[Team],$B23,PlayerMatchHistory[Result],E$15) -> 0 | F23: =(C23+E23/2)/SUM(C23:E23) -> 0.26666667
A26: PLAYER MATCH HISTORY
A27: One row per player • Singles opponents shown separately • Use this table for future website records
A28: Year | B28: Day | C28: Format | D28: Segment | E28: Player | F28: Team | G28: Teammate(s) | H28: Singles Opponent | I28: Result | J28: Score / Notes
A29: 2019 | B29: Session 1a | C29: Fourball | E29: Sam Griffiths | F29: Red | G29: Dylan Bradley | I29: L | J29: NAVY 2&1
A30: 2019 | B30: Session 1a | C30: Fourball | E30: Dylan Bradley | F30: Red | G30: Sam Griffiths | I30: L | J30: NAVY 2&1
A31: 2019 | B31: Session 1a | C31: Fourball | E31: JJ Meakings | F31: Navy | G31: Steve Wells | I31: W | J31: NAVY 2&1
A32: 2019 | B32: Session 1a | C32: Fourball | E32: Steve Wells | F32: Navy | G32: JJ Meakings | I32: W | J32: NAVY 2&1
A33: 2019 | B33: Session 1b | C33: Fourball | E33: Sean Bromley | F33: Red | G33: Kevin Catliff | I33: L | J33: NAVY 7&5
A34: 2019 | B34: Session 1b | C34: Fourball | E34: Kevin Catliff | F34: Red | G34: Sean Bromley | I34: L | J34: NAVY 7&5
A35: 2019 | B35: Session 1b | C35: Fourball | E35: Eric Bleim | F35: Navy | G35: George Collister | I35: W | J35: NAVY 7&5
A36: 2019 | B36: Session 1b | C36: Fourball | E36: George Collister | F36: Navy | G36: Eric Bleim | I36: W | J36: NAVY 7&5
A37: 2019 | B37: Session 2a | C37: Scramble | E37: Sam Griffiths | F37: Red | G37: Kevin Catliff | I37: W | J37: RED 3 under
A38: 2019 | B38: Session 2a | C38: Scramble | E38: Kevin Catliff | F38: Red | G38: Sam Griffiths | I38: W | J38: RED 3 under
A39: 2019 | B39: Session 2a | C39: Scramble | E39: JJ Meakings | F39: Navy | G39: George Collister | I39: L | J39: RED 3 under
A40: 2019 | B40: Session 2a | C40: Scramble | E40: George Collister | F40: Navy | G40: JJ Meakings | I40: L | J40: RED 3 under
... A44: 2019 | B44: Session 2b | C44: Scramble | E44: Steve Wells | F44: Navy | G44: Eric Bleim | I44: W | J44: NAVY 2 under
A45: 2019 | B45: Session 3 | C45: Singles | E45: Sam Griffiths | F45: Red | H45: JJ Meakings | I45: T | J45: A/S
A46: 2019 | B46: Session 3 | C46: Singles | E46: JJ Meakings | F46: Navy | H46: Sam Griffiths | I46: T | J46: A/S
A47: 2019 | B47: Session 3 | C47: Singles | E47: Kevin Catliff | F47: Red | H47: Eric Bleim | I47: L | J47: NAVY 2&1
A48: 2019 | B48: Session 3 | C48: Singles | E48: Eric Bleim | F48: Navy | H48: Kevin Catliff | I48: W | J48: NAVY 2&1
A49: 2019 | B49: Session 3 | C49: Singles | E49: Dylan Bradley | F49: Red | H49: George Collister | I49: L | J49: NAVY 4&3
...

Sheet Player Stats
A1: CYDER CUP • PLAYER DATABASE
A4: Player ID | B4: Display Name | C4: Team | D4: Active | E4: Career W | F4: Career L | G4: Career T | H4: Career Matches | I4: Career Win % | J4: 2026 Cup W | K4: 2026 Cup L | L4: 2026 Cup T | M4: First Name | N4: Last Name | O4: Handicap | P4: Hometown | Q4: Home Course | R4: Favorite Drink | S4: Walkout Music | T4: Bio | U4: Photo Key
A5: red-sam | B5: Sam Griffiths | C5: Red | D5: Yes | E5: 8 | F5: 6 | G5: 1 | H5: =SUM(E5:G5) -> 15 | I5: =IF(H5=0,0,(E5+G5/2)/H5) -> 0.56666667 | J5: ='Live Leaderboard'!D60 -> 0 | K5: ='Live Leaderboard'!E60 -> 0 | L5: ='Live Leaderboard'!F60 -> 0 | M5: Sam | N5: Griffiths | O5: 13 | P5: North Vancouver, British Columbia | Q5: Sunningdale Golf Club | R5: Guinness | S5: I Don’t Wanna Be – Gavin Degraw | T5: An original founder of the Cyder Cup. Sam's golf game closely mirrors his excel spreadsheets; aesthetically pleasing to the eye, often over-engineered, and on rare occasion has no #VALUE. | U5: red-sam
A6: red-kevin | B6: Kevin Catliff | C6: Red | D6: Yes | E6: 6 | F6: 8 | G6: 1 | H6: =SUM(E6:G6) -> 15 | I6: =IF(H6=0,0,(E6+G6/2)/H6) -> 0.43333333 | J6: ='Live Leaderboard'!D61 -> 0 | K6: ='Live Leaderboard'!E61 -> 0 | L6: ='Live Leaderboard'!F61 -> 0 | M6: Kevin | N6: Catliff | O6: 8 | P6: Vancouver, British Columbia | Q6: Bowen Island Golf Club | R6: Suntory | S6: Heaven Takes You Home - SHM | T6: One half of the lefty brothers. As good at sinking putts and he is sinking ping pong balls. Proudly hold the worst athleticism-to-swing speed ratio. | U6: red-kevin
A7: red-sean | B7: Sean Bromley | C7: Red | D7: Yes | E7: 5 | F7: 10 | G7: 0 | H7: =SUM(E7:G7) -> 15 | I7: =IF(H7=0,0,(E7+G7/2)/H7) -> 0.33333333 | J7: ='Live Leaderboard'!D62 -> 0 | K7: ='Live Leaderboard'!E62 -> 0 | L7: ='Live Leaderboard'!F62 -> 0 | M7: Sean | N7: Bromley | O7: 21 | P7: Vancouver, British Columbia | Q7: Capilano Golf and Country Club | R7: Whiskey | S7: Beer Never Broke My Heart - Luke Combs | T7: Sean has become the sneaky backbone of the Cyder Cup culture. Whether its his energy or his golf, Sean never goes below 100. | U7: red-sean
A8: red-dylan | B8: Dylan Bradley | C8: Red | D8: Yes | E8: 4 | F8: 11 | G8: 0 | H8: =SUM(E8:G8) -> 15 | I8: =IF(H8=0,0,(E8+G8/2)/H8) -> 0.26666667 | J8: ='Live Leaderboard'!D63 -> 0 | K8: ='Live Leaderboard'!E63 -> 0 | L8: ='Live Leaderboard'!F63 -> 0 | M8: Dylan | N8: Bradley | O8: 15 | P8: Pitt Meadows, British Columbia | Q8: Pitt Meadows Golf Club | R8: Tequila Soda | S8: Shook Ones – Mobb Deep | T8: Breaking records and breaking (his own) bones. Known for his fiery personality, Dylan spends Cyder Cup weekend seeing red—both physically and mentally. No player is more due for a breakout performance in 2026. | U8: red-dylan
A9: navy-eric | B9: Eric Bleim | C9: Navy | D9: Yes | E9: 8 | F9: 7 | G9: 0 | H9: =SUM(E9:G9) -> 15 | I9: =IF(H9=0,0,(E9+G9/2)/H9) -> 0.53333333 | J9: ='Live Leaderboard'!D64 -> 0 | K9: ='Live Leaderboard'!E64 -> 0 | L9: ='Live Leaderboard'!F64 -> 0 | M9: Eric | N9: Bleim | O9: 16 | P9: North Vancouver, British Columbia | Q9: The Redwoods Golf Course | R9: Orange Crush (zero sugar) | S9: Pink Pony Club – Chappell Roan | T9: An original founder of the Cyder Cup. Currently seeing the numbers on the scale go down and numbers on the scorecard go up. | U9: navy-eric
A10: navy-george | B10: George Collister | C10: Navy | D10: Yes | E10: 9 | F10: 6 | G10: 0 | H10: =SUM(E10:G10) -> 15 | I10: =IF(H10=0,0,(E10+G10/2)/H10) -> 0.6 | J10: ='Live Leaderboard'!D65 -> 0 | K10: ='Live Leaderboard'!E65 -> 0 | L10: ='Live Leaderboard'!F65 -> 0 | M10: George | N10: Collister | O10: 12 | P10: Langley, British Columbia | Q10: The Redwoods Golf Course | R10: Miller Lite | S10: Money for nothing – Dire Straights | T10: George can't flip a cup but he can certainly flip a match. Known for bringing his corporate professionalism to the party. | U10: navy-george
A11: navy-steven | B11: Steve Wells | C11: Navy | D11: Yes | E11: 10 | F11: 5 | G11: 0 | H11: =SUM(E11:G11) -> 15 | I11: =IF(H11=0,0,(E11+G11/2)/H11) -> 0.66666667 | J11: ='Live Leaderboard'!D66 -> 0 | K11: ='Live Leaderboard'!E66 -> 0 | L11: ='Live Leaderboard'!F66 -> 0 | M11: Steve | N11: Wells | O11: 24 | P11: North Vancouver, British Columbia | Q11: Royal Porthcawl | R11: Peppermint tea | S11: Holding out for a Hero - RIP Bonnie | T11: Regarded as the Dad of the group. Steve's special talent is his ability to 4-putt multiple times in a round yet still not lose. Team Navy's most winningest player in the history of the Cyder Cup. | U11: navy-steve
A12: navy-jj | B12: JJ Meakings | C12: Navy | D12: Yes | E12: 8 | F12: 5 | G12: 2 | H12: =SUM(E12:G12) -> 15 | I12: =IF(H12=0,0,(E12+G12/2)/H12) -> 0.6 | J12: ='Live Leaderboard'!D67 -> 0 | K12: ='Live Leaderboard'!E67 -> 0 | L12: ='Live Leaderboard'!F67 -> 0 | M12: JJ | N12: Meakings | O12: 5 | P12: Scottsdale, Arizona | Q12: Trilogy Golf Club at Vistancia | R12: Diet Coke | S12: Talk of the Town – Fred Again | T12: Running away from his problems in Scottsdale, Arizona, JJ is known for playing good golf every weekend except the Cyder Cup weekend. Only player to bring extras clubs to the Cyder Cup given the high likelihood one gets snapped in half or stuck in a tree. | U12: navy-jj
A15: PURPOSE: canonical player names and IDs for dropdowns, statistics, profiles, and website URLs

Sheet Feed - Matches
A1: match_id | B1: tournament_id | C1: session_id | D1: match_number | E1: event_name | F1: format | G1: status | H1: tee_group | I1: navy_player_1 | J1: navy_player_2 | K1: red_player_1 | L1: red_player_2 | M1: scheduled_date | N1: start_time | O1: current_hole | P1: display_score | Q1: front_9 | R1: back_9 | S1: total_score | T1: result | U1: navy_points | V1: red_points | W1: points_available
A2: ="scramble-1" -> scramble-1 | B2: ="cyder-cup-2026" -> cyder-cup-2026 | C2: ="session-1" -> session-1 | D2: =1 -> 1 | E2: Team Navy Scramble | F2: ="scramble" -> scramble | G2: ='Live Leaderboard'!F15 -> Not Started | H2: Group 1 | I2: ="all-navy" -> all-navy | M2: 46254 | N2: 3:40pm | O2: ="" | P2: ='Live Leaderboard'!E15 -> 0 | T2: =IF(OR('Live Leaderboard'!D15="",'Live Leaderboard'!D15=0),"",IF(LOWER('Live Leaderboard'!D15)="navy","navy",IF(LOWER('Live Leaderboard'!D15)="red","red","halved"))) | U2: ='Live Leaderboard'!H15+'Live Leaderboard'!H16+'Live Leaderboard'!H17 -> 0 | V2: ='Live Leaderboard'!G15+'Live Leaderboard'!G16+'Live Leaderboard'!G17 -> 0 | W2: ='Live Leaderboard'!C15+'Live Leaderboard'!C16+'Live Leaderboard'!C17 -> 3
A3: ="scramble-2" -> scramble-2 | B3: ="cyder-cup-2026" -> cyder-cup-2026 | C3: ="session-1" -> session-1 | D3: =D2+1 -> 2 | E3: Team Red Scramble | F3: ="scramble" -> scramble | G3: ='Live Leaderboard'!F16 -> Not Started | H3: Group 2 | K3: ="all-red" -> all-red | M3: 46254 | N3: 3:50pm | P3: ='Live Leaderboard'!E16 -> 0 | T3: =IF(OR('Live Leaderboard'!D16="",'Live Leaderboard'!D16=0),"",IF(LOWER('Live Leaderboard'!D16)="navy","navy",IF(LOWER('Live Leaderboard'!D16)="red","red","halved"))) | U3: ='Live Leaderboard'!H16+'Live Leaderboard'!H17+'Live Leaderboard'!H18 -> 0 | V3: ='Live Leaderboard'!G16+'Live Leaderboard'!G17+'Live Leaderboard'!G18 -> 0 | W3: ='Live Leaderboard'!C16+'Live Leaderboard'!C17+'Live Leaderboard'!C18 -> 3
A4: ="fourball-1" -> fourball-1 | B4: ="cyder-cup-2026" -> cyder-cup-2026 | C4: ="session-4" -> session-4 | D4: =1 -> 1 | E4: ="Fourball #1" -> Fourball #1 | F4: ="fourball" -> fourball | G4: ='Live Leaderboard'!J27 -> Not Started | H4: Group 1 | I4: =IF('Live Leaderboard'!F27="","",IFERROR(INDEX('Player Stats'!$A$5:$A$12,MATCH('Live Leaderboard'!F27,'Player Stats'!$B$5:$B$12,0)),"")) -> navy-jj | J4: =IF('Live Leaderboard'!G27="","",IFERROR(INDEX('Player Stats'!$A$5:$A$12,MATCH('Live Leaderboard'!G27,'Player Stats'!$B$5:$B$12,0)),"")) -> navy-eric | K4: =IF('Live Leaderboard'!D27="","",IFERROR(INDEX('Player Stats'!$A$5:$A$12,MATCH('Live Leaderboard'!D27,'Player Stats'!$B$5:$B$12,0)),"")) -> red-kevin | L4: =IF('Live Leaderboard'!E27="","",IFERROR(INDEX('Player Stats'!$A$5:$A$12,MATCH('Live Leaderboard'!E27,'Player Stats'!$B$5:$B$12,0)),"")) -> red-sam | M4: 46255 | N4: 1:00pm | O4: ="" | P4: ='Live Leaderboard'!I27 -> 0 | T4: =IF(OR('Live Leaderboard'!H27="",'Live Leaderboard'!H27=0),"",IF(LOWER('Live Leaderboard'!H27)="navy","navy",IF(LOWER('Live Leaderboard'!H27)="red","red","halved"))) | U4: ='Live Leaderboard'!L28+'Live Leaderboard'!L29+'Live Leaderboard'!L30 -> 0 | V4: ='Live Leaderboard'!K28+'Live Leaderboard'!K29+'Live Leaderboard'!K30 -> 0 | W4: ='Live Leaderboard'!C28+'Live Leaderboard'!C29+'Live Leaderboard'!C30 -> 3
A5: ="fourball-2" -> fourball-2 | B5: ="cyder-cup-2026" -> cyder-cup-2026 | C5: ="session-4" -> session-4 | D5: =D4+1 -> 2 | E5: ="Fourball #2" -> Fourball #2 | F5: ="fourball" -> fourball | G5: ='Live Leaderboard'!J32 -> Not Started | H5: Group 2 | I5: =IF('Live Leaderboard'!F32="","",IFERROR(INDEX('Player Stats'!$A$5:$A$12,MATCH('Live Leaderboard'!F32,'Player Stats'!$B$5:$B$12,0)),"")) -> navy-steven | J5: =IF('Live Leaderboard'!G32="","",IFERROR(INDEX('Player Stats'!$A$5:$A$12,MATCH('Live Leaderboard'!G32,'Player Stats'!$B$5:$B$12,0)),"")) -> navy-george | K5: =IF('Live Leaderboard'!D32="","",IFERROR(INDEX('Player Stats'!$A$5:$A$12,MATCH('Live Leaderboard'!D32,'Player Stats'!$B$5:$B$12,0)),"")) -> red-sean | L5: =IF('Live Leaderboard'!E32="","",IFERROR(INDEX('Player Stats'!$A$5:$A$12,MATCH('Live Leaderboard'!E32,'Player Stats'!$B$5:$B$12,0)),"")) -> red-dylan | M5: 46255 | N5: 1:10pm | O5: ="" | P5: ='Live Leaderboard'!I32 -> 0 | T5: =IF(OR('Live Leaderboard'!H32="",'Live Leaderboard'!H32=0),"",IF(LOWER('Live Leaderboard'!H32)="navy","navy",IF(LOWER('Live Leaderboard'!H32)="red","red","halved"))) | U5: ='Live Leaderboard'!L33+'Live Leaderboard'!L34+'Live Leaderboard'!L35 -> 0 | V5: ='Live Leaderboard'!K33+'Live Leaderboard'!K34+'Live Leaderboard'!K35 -> 0 | W5: ='Live Leaderboard'!C33+'Live Leaderboard'!C34+'Live Leaderboard'!C35 -> 3
A6: ="singles-1" -> singles-1 | B6: ="cyder-cup-2026" -> cyder-cup-2026 | C6: ="session-8" -> session-8 | D6: 1 | E6: ="Singles #1" -> Singles #1 | F6: ="singles" -> singles | G6: ='Live Leaderboard'!J37 -> Not Started | H6: Group 1 | I6: =IF('Live Leaderboard'!F37="","",IFERROR(INDEX('Player Stats'!$A$5:$A$12,MATCH('Live Leaderboard'!F37,'Player Stats'!$B$5:$B$12,0)),"")) -> navy-jj | J6: ="" | K6: =IF('Live Leaderboard'!D37="","",IFERROR(INDEX('Player Stats'!$A$5:$A$12,MATCH('Live Leaderboard'!D37,'Player Stats'!$B$5:$B$12,0)),"")) -> red-sam | L6: ="" | M6: 46256 | N6: 1:00pm | O6: ="" | P6: ='Live Leaderboard'!I37 -> 0 | T6: =IF(OR('Live Leaderboard'!H37="",'Live Leaderboard'!H37=0),"",IF(LOWER('Live Leaderboard'!H37)="navy","navy",IF(LOWER('Live Leaderboard'!H37)="red","red","halved"))) | U6: ='Live Leaderboard'!L38+'Live Leaderboard'!L39+'Live Leaderboard'!L40 -> 0 | V6: ='Live Leaderboard'!K38+'Live Leaderboard'!K39+'Live Leaderboard'!K40 -> 0 | W6: ='Live Leaderboard'!C38+'Live Leaderboard'!C39+'Live Leaderboard'!C40 -> 4
A7: ="singles-2" -> singles-2 | B7: ="cyder-cup-2026" -> cyder-cup-2026 | C7: ="session-8" -> session-8 | D7: 2 | E7: ="Singles #2" -> Singles #2 | F7: ="singles" -> singles | G7: ='Live Leaderboard'!J42 -> Not Started | H7: Group 1 | I7: =IF('Live Leaderboard'!F42="","",IFERROR(INDEX('Player Stats'!$A$5:$A$12,MATCH('Live Leaderboard'!F42,'Player Stats'!$B$5:$B$12,0)),"")) -> navy-steven | J7: ="" | K7: =IF('Live Leaderboard'!D42="","",IFERROR(INDEX('Player Stats'!$A$5:$A$12,MATCH('Live Leaderboard'!D42,'Player Stats'!$B$5:$B$12,0)),"")) -> red-kevin | L7: ="" | M7: 46256 | N7: 1:10pm | O7: ="" | P7: ='Live Leaderboard'!I42 -> 0 | T7: =IF(OR('Live Leaderboard'!H42="",'Live Leaderboard'!H42=0),"",IF(LOWER('Live Leaderboard'!H42)="navy","navy",IF(LOWER('Live Leaderboard'!H42)="red","red","halved"))) | U7: ='Live Leaderboard'!L43+'Live Leaderboard'!L44+'Live Leaderboard'!L45 -> 0 | V7: ='Live Leaderboard'!K43+'Live Leaderboard'!K44+'Live Leaderboard'!K45 -> 0 | W7: ='Live Leaderboard'!C43+'Live Leaderboard'!C44+'Live Leaderboard'!C45 -> 4
A8: ="singles-3" -> singles-3 | B8: ="cyder-cup-2026" -> cyder-cup-2026 | C8: ="session-8" -> session-8 | D8: 3 | E8: ="Singles #3" -> Singles #3 | F8: ="singles" -> singles | G8: ='Live Leaderboard'!J47 -> Not Started | H8: Group 2 | I8: =IF('Live Leaderboard'!F47="","",IFERROR(INDEX('Player Stats'!$A$5:$A$12,MATCH('Live Leaderboard'!F47,'Player Stats'!$B$5:$B$12,0)),"")) -> navy-george | J8: ="" | K8: =IF('Live Leaderboard'!D47="","",IFERROR(INDEX('Player Stats'!$A$5:$A$12,MATCH('Live Leaderboard'!D47,'Player Stats'!$B$5:$B$12,0)),"")) -> red-sean | L8: ="" | M8: 46256 | N8: 1:20pm | O8: ="" | P8: ='Live Leaderboard'!I47 -> 0 | T8: =IF(OR('Live Leaderboard'!H47="",'Live Leaderboard'!H47=0),"",IF(LOWER('Live Leaderboard'!H47)="navy","navy",IF(LOWER('Live Leaderboard'!H47)="red","red","halved"))) | U8: ='Live Leaderboard'!L48+'Live Leaderboard'!L49+'Live Leaderboard'!L50 -> 0 | V8: ='Live Leaderboard'!K48+'Live Leaderboard'!K49+'Live Leaderboard'!K50 -> 0 | W8: ='Live Leaderboard'!C48+'Live Leaderboard'!C49+'Live Leaderboard'!C50 -> 4
A9: ="singles-4" -> singles-4 | B9: ="cyder-cup-2026" -> cyder-cup-2026 | C9: ="session-8" -> session-8 | D9: 4 | E9: ="Singles #4" -> Singles #4 | F9: ="singles" -> singles | G9: ='Live Leaderboard'!J52 -> Not Started | H9: Group 2 | I9: =IF('Live Leaderboard'!F52="","",IFERROR(INDEX('Player Stats'!$A$5:$A$12,MATCH('Live Leaderboard'!F52,'Player Stats'!$B$5:$B$12,0)),"")) -> navy-eric | J9: ="" | K9: =IF('Live Leaderboard'!D52="","",IFERROR(INDEX('Player Stats'!$A$5:$A$12,MATCH('Live Leaderboard'!D52,'Player Stats'!$B$5:$B$12,0)),"")) -> red-dylan | L9: ="" | M9: 46256 | N9: 1:30pm | O9: ="" | P9: ='Live Leaderboard'!I52 -> 0 | T9: =IF(OR('Live Leaderboard'!H52="",'Live Leaderboard'!H52=0),"",IF(LOWER('Live Leaderboard'!H52)="navy","navy",IF(LOWER('Live Leaderboard'!H52)="red","red","halved"))) | U9: ='Live Leaderboard'!L53+'Live Leaderboard'!L54+'Live Leaderboard'!L55 -> 0 | V9: ='Live Leaderboard'!K53+'Live Leaderboard'!K54+'Live Leaderboard'!K55 -> 0 | W9: ='Live Leaderboard'!C53+'Live Leaderboard'!C54+'Live Leaderboard'!C55 -> 4
A10: ="Evening Events-1" -> Evening Events-1 | B10: ="cyder-cup-2026" -> cyder-cup-2026 | C10: ="session-2" -> session-2 | D10: 1 | E10: Chesties | F10: ="drinking-game" -> drinking-game | G10: ='Live Leaderboard'!F18 -> Not Started | I10: ="all-navy" -> all-navy | K10: ="all-red" -> all-red | M10: 46254 | N10: 9:00pm | O10: ="" | P10: ='Live Leaderboard'!E18 -> 0 | T10: =IF(OR('Live Leaderboard'!H53="",'Live Leaderboard'!H53=0),"",IF(LOWER('Live Leaderboard'!H53)="navy","navy",IF(LOWER('Live Leaderboard'!H53)="red","red","halved"))) | U10: ='Live Leaderboard'!H18 -> 0 | V10: ='Live Leaderboard'!G18 -> 0 | W10: ='Live Leaderboard'!C18 -> 1
A11: ="Evening Events-2" -> Evening Events-2 | B11: ="cyder-cup-2026" -> cyder-cup-2026 | C11: ="session-3" -> session-3 | D11: 2 | E11: Flip cup | F11: ="drinking-game" -> drinking-game | G11: ='Live Leaderboard'!F19 -> Not Started | I11: ="all-navy" -> all-navy | K11: ="all-red" -> all-red | M11: 46254 | N11: 10:00pm | P11: ='Live Leaderboard'!E19 -> 0 | U11: ='Live Leaderboard'!H19 -> 0 | V11: ='Live Leaderboard'!G19 -> 0 | W11: ='Live Leaderboard'!C19 -> 1
A12: ="Evening Events-3" -> Evening Events-3 | B12: ="cyder-cup-2026" -> cyder-cup-2026 | C12: ="session-5" -> session-5 | D12: 3 | E12: Beer pong | F12: ="drinking-game" -> drinking-game | G12: ='Live Leaderboard'!F20 -> Not Started | I12: ="all-navy" -> all-navy | K12: ="all-red" -> all-red | M12: 46255 | N12: 8:00pm | P12: ='Live Leaderboard'!E20 -> 0 | U12: ='Live Leaderboard'!H20 -> 0 | V12: ='Live Leaderboard'!G20 -> 0 | W12: ='Live Leaderboard'!C20 -> 1
A13: ="Evening Events-4" -> Evening Events-4 | B13: ="cyder-cup-2026" -> cyder-cup-2026 | C13: ="session-6" -> session-6 | D13: 4 | E13: Relay race | F13: ="drinking-game" -> drinking-game | G13: ='Live Leaderboard'!F21 -> Not Started | I13: ="all-navy" -> all-navy | K13: ="all-red" -> all-red | M13: 46255 | N13: 9:00pm | P13: ='Live Leaderboard'!E21 -> 0 | U13: ='Live Leaderboard'!H21 -> 0 | V13: ='Live Leaderboard'!G21 -> 0 | W13: ='Live Leaderboard'!C21 -> 1
A14: ="Evening Events-5" -> Evening Events-5 | B14: ="cyder-cup-2026" -> cyder-cup-2026 | C14: ="session-7" -> session-7 | D14: 5 | E14: Beer darts | F14: ="drinking-game" -> drinking-game | G14: ='Live Leaderboard'!F22 -> Not Started | I14: ="all-navy" -> all-navy | K14: ="all-red" -> all-red | M14: 46255 | N14: 10:00pm | P14: ='Live Leaderboard'!E22 -> 0 | U14: ='Live Leaderboard'!H22 -> 0 | V14: ='Live Leaderboard'!G22 -> 0 | W14: ='Live Leaderboard'!C22 -> 1

Sheet Feed - Players
A1: player_id | B1: first_name | C1: last_name | D1: display_name | E1: team_id | F1: active | G1: handicap | H1: hometown | I1: home_course | J1: favorite_drink | K1: walkout_music | L1: bio | M1: career_wins | N1: career_losses | O1: career_ties | P1: career_matches | Q1: career_points | R1: career_points_percentage | S1: photo_key
A2: ='Player Stats'!A5 -> red-sam | B2: ='Player Stats'!M5 -> Sam | C2: ='Player Stats'!N5 -> Griffiths | D2: ='Player Stats'!B5 -> Sam Griffiths | E2: =LOWER('Player Stats'!C5) -> red | F2: =IF('Player Stats'!D5="Yes",TRUE,FALSE) -> TRUE | G2: ='Player Stats'!O5 -> 13 | H2: ='Player Stats'!P5 -> North Vancouver, British Columbia | I2: ='Player Stats'!Q5 -> Sunningdale Golf Club | J2: ='Player Stats'!R5 -> Guinness | K2: ='Player Stats'!S5 -> I Don’t Wanna Be – Gavin Degraw | L2: ='Player Stats'!T5 -> An original founder of the Cyder Cup. Sam's golf game closely mirrors his excel spreadsheets; aesthetically pleasing to the eye, often over-engineered, and on rare occasion has no #VALUE. | M2: ='Player Stats'!E5 -> 8 | N2: ='Player Stats'!F5 -> 6 | O2: ='Player Stats'!G5 -> 1 | P2: ='Player Stats'!H5 -> 15 | Q2: ='Player Stats'!E5+'Player Stats'!G5*0.5 -> 8.5 | R2: ='Player Stats'!I5 -> 0.56666667 | S2: ='Player Stats'!U5 -> red-sam
A3: ='Player Stats'!A6 -> red-kevin | B3: ='Player Stats'!M6 -> Kevin | C3: ='Player Stats'!N6 -> Catliff | D3: ='Player Stats'!B6 -> Kevin Catliff | E3: =LOWER('Player Stats'!C6) -> red | F3: =IF('Player Stats'!D6="Yes",TRUE,FALSE) -> TRUE | G3: ='Player Stats'!O6 -> 8 | H3: ='Player Stats'!P6 -> Vancouver, British Columbia | I3: ='Player Stats'!Q6 -> Bowen Island Golf Club | J3: ='Player Stats'!R6 -> Suntory | K3: ='Player Stats'!S6 -> Heaven Takes You Home - SHM | L3: ='Player Stats'!T6 -> One half of the lefty brothers. As good at sinking putts and he is sinking ping pong balls. Proudly hold the worst athleticism-to-swing speed ratio. | M3: ='Player Stats'!E6 -> 6 | N3: ='Player Stats'!F6 -> 8 | O3: ='Player Stats'!G6 -> 1 | P3: ='Player Stats'!H6 -> 15 | Q3: ='Player Stats'!E6+'Player Stats'!G6*0.5 -> 6.5 | R3: ='Player Stats'!I6 -> 0.43333333 | S3: ='Player Stats'!U6 -> red-kevin
A4: ='Player Stats'!A7 -> red-sean | B4: ='Player Stats'!M7 -> Sean | C4: ='Player Stats'!N7 -> Bromley | D4: ='Player Stats'!B7 -> Sean Bromley | E4: =LOWER('Player Stats'!C7) -> red | F4: =IF('Player Stats'!D7="Yes",TRUE,FALSE) -> TRUE | G4: ='Player Stats'!O7 -> 21 | H4: ='Player Stats'!P7 -> Vancouver, British Columbia | I4: ='Player Stats'!Q7 -> Capilano Golf and Country Club | J4: ='Player Stats'!R7 -> Whiskey | K4: ='Player Stats'!S7 -> Beer Never Broke My Heart - Luke Combs | L4: ='Player Stats'!T7 -> Sean has become the sneaky backbone of the Cyder Cup culture. Whether its his energy or his golf, Sean never goes below 100. | M4: ='Player Stats'!E7 -> 5 | N4: ='Player Stats'!F7 -> 10 | O4: ='Player Stats'!G7 -> 0 | P4: ='Player Stats'!H7 -> 15 | Q4: ='Player Stats'!E7+'Player Stats'!G7*0.5 -> 5 | R4: ='Player Stats'!I7 -> 0.33333333 | S4: ='Player Stats'!U7 -> red-sean
A5: ='Player Stats'!A8 -> red-dylan | B5: ='Player Stats'!M8 -> Dylan | C5: ='Player Stats'!N8 -> Bradley | D5: ='Player Stats'!B8 -> Dylan Bradley | E5: =LOWER('Player Stats'!C8) -> red | F5: =IF('Player Stats'!D8="Yes",TRUE,FALSE) -> TRUE | G5: ='Player Stats'!O8 -> 15 | H5: ='Player Stats'!P8 -> Pitt Meadows, British Columbia | I5: ='Player Stats'!Q8 -> Pitt Meadows Golf Club | J5: ='Player Stats'!R8 -> Tequila Soda | K5: ='Player Stats'!S8 -> Shook Ones – Mobb Deep | L5: ='Player Stats'!T8 -> Breaking records and breaking (his own) bones. Known for his fiery personality, Dylan spends Cyder Cup weekend seeing red—both physically and mentally. No player is more due for a breakout performance in 2026. | M5: ='Player Stats'!E8 -> 4 | N5: ='Player Stats'!F8 -> 11 | O5: ='Player Stats'!G8 -> 0 | P5: ='Player Stats'!H8 -> 15 | Q5: ='Player Stats'!E8+'Player Stats'!G8*0.5 -> 4 | R5: ='Player Stats'!I8 -> 0.26666667 | S5: ='Player Stats'!U8 -> red-dylan
A6: ='Player Stats'!A9 -> navy-eric | B6: ='Player Stats'!M9 -> Eric | C6: ='Player Stats'!N9 -> Bleim | D6: ='Player Stats'!B9 -> Eric Bleim | E6: =LOWER('Player Stats'!C9) -> navy | F6: =IF('Player Stats'!D9="Yes",TRUE,FALSE) -> TRUE | G6: ='Player Stats'!O9 -> 16 | H6: ='Player Stats'!P9 -> North Vancouver, British Columbia | I6: ='Player Stats'!Q9 -> The Redwoods Golf Course | J6: ='Player Stats'!R9 -> Orange Crush (zero sugar) | K6: ='Player Stats'!S9 -> Pink Pony Club – Chappell Roan | L6: ='Player Stats'!T9 -> An original founder of the Cyder Cup. Currently seeing the numbers on the scale go down and numbers on the scorecard go up. | M6: ='Player Stats'!E9 -> 8 | N6: ='Player Stats'!F9 -> 7 | O6: ='Player Stats'!G9 -> 0 | P6: ='Player Stats'!H9 -> 15 | Q6: ='Player Stats'!E9+'Player Stats'!G9*0.5 -> 8 | R6: ='Player Stats'!I9 -> 0.53333333 | S6: ='Player Stats'!U9 -> navy-eric
A7: ='Player Stats'!A10 -> navy-george | B7: ='Player Stats'!M10 -> George | C7: ='Player Stats'!N10 -> Collister | D7: ='Player Stats'!B10 -> George Collister | E7: =LOWER('Player Stats'!C10) -> navy | F7: =IF('Player Stats'!D10="Yes",TRUE,FALSE) -> TRUE | G7: ='Player Stats'!O10 -> 12 | H7: ='Player Stats'!P10 -> Langley, British Columbia | I7: ='Player Stats'!Q10 -> The Redwoods Golf Course | J7: ='Player Stats'!R10 -> Miller Lite | K7: ='Player Stats'!S10 -> Money for nothing – Dire Straights | L7: ='Player Stats'!T10 -> George can't flip a cup but he can certainly flip a match. Known for bringing his corporate professionalism to the party. | M7: ='Player Stats'!E10 -> 9 | N7: ='Player Stats'!F10 -> 6 | O7: ='Player Stats'!G10 -> 0 | P7: ='Player Stats'!H10 -> 15 | Q7: ='Player Stats'!E10+'Player Stats'!G10*0.5 -> 9 | R7: ='Player Stats'!I10 -> 0.6 | S7: ='Player Stats'!U10 -> navy-george
A8: ='Player Stats'!A11 -> navy-steven | B8: ='Player Stats'!M11 -> Steve | C8: ='Player Stats'!N11 -> Wells | D8: ='Player Stats'!B11 -> Steve Wells | E8: =LOWER('Player Stats'!C11) -> navy | F8: =IF('Player Stats'!D11="Yes",TRUE,FALSE) -> TRUE | G8: ='Player Stats'!O11 -> 24 | H8: ='Player Stats'!P11 -> North Vancouver, British Columbia | I8: ='Player Stats'!Q11 -> Royal Porthcawl | J8: ='Player Stats'!R11 -> Peppermint tea | K8: ='Player Stats'!S11 -> Holding out for a Hero - RIP Bonnie | L8: ='Player Stats'!T11 -> Regarded as the Dad of the group. Steve's special talent is his ability to 4-putt multiple times in a round yet still not lose. Team Navy's most winningest player in the history of the Cyder Cup. | M8: ='Player Stats'!E11 -> 10 | N8: ='Player Stats'!F11 -> 5 | O8: ='Player Stats'!G11 -> 0 | P8: ='Player Stats'!H11 -> 15 | Q8: ='Player Stats'!E11+'Player Stats'!G11*0.5 -> 10 | R8: ='Player Stats'!I11 -> 0.66666667 | S8: ='Player Stats'!U11 -> navy-steve
A9: ='Player Stats'!A12 -> navy-jj | B9: ='Player Stats'!M12 -> JJ | C9: ='Player Stats'!N12 -> Meakings | D9: ='Player Stats'!B12 -> JJ Meakings | E9: =LOWER('Player Stats'!C12) -> navy | F9: =IF('Player Stats'!D12="Yes",TRUE,FALSE) -> TRUE | G9: ='Player Stats'!O12 -> 5 | H9: ='Player Stats'!P12 -> Scottsdale, Arizona | I9: ='Player Stats'!Q12 -> Trilogy Golf Club at Vistancia | J9: ='Player Stats'!R12 -> Diet Coke | K9: ='Player Stats'!S12 -> Talk of the Town – Fred Again | L9: ='Player Stats'!T12 -> Running away from his problems in Scottsdale, Arizona, JJ is known for playing good golf every weekend except the Cyder Cup weekend. Only player to bring extras clubs to the Cyder Cup given the high likelihood one gets snapped in half or stuck in a tree. | M9: ='Player Stats'!E12 -> 8 | N9: ='Player Stats'!F12 -> 5 | O9: ='Player Stats'!G12 -> 2 | P9: ='Player Stats'!H12 -> 15 | Q9: ='Player Stats'!E12+'Player Stats'!G12*0.5 -> 9 | R9: ='Player Stats'!I12 -> 0.6 | S9: ='Player Stats'!U12 -> navy-jj

Sheet Feed - Tournaments
A1: tournament_id | B1: year | C1: name | D1: venue | E1: city | F1: region | G1: country | H1: start_date | I1: end_date | J1: status | K1: winning_team | L1: navy_points | M1: red_points | N1: points_to_win | O1: winning captain | P1: mvp_player_id | Q1: summary | R1: full_write_up | S1: hero_image_key | T1: gallery_folder | U1: format_label | V1: content_status
A2: ="cyder-cup-"&TEXT('Record Book'!A7,"0") -> cyder-cup-2019 | B2: ='Record Book'!A7 -> 2019 | C2: ="Cyder Cup "&TEXT(B2,"0") -> Cyder Cup 2019 | D2: Tobiano Golf Course | The Dunes Golf Course | Sun Peaks Golf Course | E2: Kamloops | F2: British Columbia | G2: Canada | H2: 43680 | I2: 43682 | J2: ="complete" -> complete | K2: =LOWER('Record Book'!B7) -> navy | L2: ='Record Book'!F7 -> 13.5 | M2: ='Record Book'!E7 -> 1.5 | N2: =15.5 -> 15.5 | O2: ='Record Book'!C7 -> Eric Bleim | P2: ="" | Q2: ="The "&TEXT(B2,"0")&" Cyder Cup was won by Team "&PROPER(K2)&" "&'Record Book'!D7&"." -> The 2019 Cyder Cup was won by Team Navy 13.5 - 1.5. | T2: history/2019 | V2: Published
A3: ="cyder-cup-"&TEXT('Record Book'!A8,"0") -> cyder-cup-2020 | B3: ='Record Book'!A8 -> 2020 | C3: ="Cyder Cup "&TEXT(B3,"0") -> Cyder Cup 2020 | D3: Tobiano Golf Course | Eaglepoint Golf Resort | Bighorn Golf and Country Club | E3: Kamloops | F3: British Columbia | G3: Canada | H3: 44044 | I3: 44046 | J3: ="complete" -> complete | K3: =LOWER('Record Book'!B8) -> red | L3: ='Record Book'!F8 -> 5 | M3: ='Record Book'!E8 -> 10 | N3: =15.5 -> 15.5 | O3: ='Record Book'!C8 -> Kevin Catliff | P3: ="" | Q3: ="The "&TEXT(B3,"0")&" Cyder Cup was won by Team "&PROPER(K3)&" "&'Record Book'!D8&"." -> The 2020 Cyder Cup was won by Team Red 10 - 5. | T3: history/2020 | V3: Published
A4: ="cyder-cup-"&TEXT('Record Book'!A9,"0") -> cyder-cup-2021 | B4: ='Record Book'!A9 -> 2021 | C4: ="Cyder Cup "&TEXT(B4,"0") -> Cyder Cup 2021 | D4: Tobiano Golf Course | Talking Rock Golf Resort | Sun Peaks Golf Resort | E4: Kamloops | F4: British Columbia | G4: Canada | H4: 44385 | I4: 44387 | J4: ="complete" -> complete | K4: =LOWER('Record Book'!B9) -> red | L4: ='Record Book'!F9 -> 6 | M4: ='Record Book'!E9 -> 9 | N4: =15.5 -> 15.5 | O4: ='Record Book'!C9 -> Dylan Bradley | P4: ="" | Q4: ="The "&TEXT(B4,"0")&" Cyder Cup was won by Team "&PROPER(K4)&" "&'Record Book'!D9&"." -> The 2021 Cyder Cup was won by Team Red 9 - 6. | T4: history/2021 | V4: Published
A5: ="cyder-cup-"&TEXT('Record Book'!A10,"0") -> cyder-cup-2022 | B5: ='Record Book'!A10 -> 2022 | C5: ="Cyder Cup "&TEXT(B5,"0") -> Cyder Cup 2022 | D5: Nicklaus North Golf Course | Big Sky Golf Club | Sunstone Golf Club | E5: Pemberton | F5: British Columbia | G5: Canada | H5: 44792 | I5: 44794 | J5: ="complete" -> complete | K5: =LOWER('Record Book'!B10) -> navy | L5: ='Record Book'!F10 -> 8 | M5: ='Record Book'!E10 -> 7 | N5: =15.5 -> 15.5 | O5: ='Record Book'!C10 -> JJ Meakings | P5: ="" | Q5: ="The "&TEXT(B5,"0")&" Cyder Cup was won by Team "&PROPER(K5)&" "&'Record Book'!D10&"." -> The 2022 Cyder Cup was won by Team Navy 8 - 7. | T5: history/2022 | V5: Published
A6: ="cyder-cup-"&TEXT('Record Book'!A11,"0") -> cyder-cup-2025 | B6: ='Record Book'!A11 -> 2025 | C6: ="Cyder Cup "&TEXT(B6,"0") -> Cyder Cup 2025 | D6: Fairmont Chateau | Big Sky Golf Club | Whistler Golf Course | E6: Whistler | F6: British Columbia | G6: Canada | H6: 45881 | I6: 45884 | J6: ="complete" -> complete | K6: =LOWER('Record Book'!B11) -> navy | L6: ='Record Book'!F11 -> 9.5 | M6: ='Record Book'!E11 -> 5.5 | N6: =15.5 -> 15.5 | O6: ='Record Book'!C11 -> Eric Bleim | P6: ="" | Q6: ="The "&TEXT(B6,"0")&" Cyder Cup was won by Team "&PROPER(K6)&" "&'Record Book'!D11&"." -> The 2025 Cyder Cup was won by Team Navy 9.5 - 5.5. | T6: history/2025 | U6: Team Vs. Team 4-man Scramble | V6: Published
A7: cyder-cup-2026 | B7: 2026 | C7: Cyder Cup 2026 | D7: Predator Ridge Golf Club | Predator Ridge Resort | E7: Vernon | F7: British Columbia | G7: Canada | H7: 46254 | I7: 46257 | J7: upcoming | L7: ='Live Leaderboard'!A7 -> 0 | M7: ='Live Leaderboard'!I7 -> 0 | N7: ='Live Leaderboard'!B3 -> 15.5 | Q7: The 2026 Cyder Cup is the current tournament. | T7: history/2026 | U7: Team Vs. Team 4-man Scramble | V7: Draft

Sheet Feed - Records
A1: record_id | B1: category | C1: title | D1: holder_type | E1: player_id | F1: team_id | G1: holder_name | H1: value | I1: display_value | J1: year | K1: description | L1: sort_order | N1: captain_name | O1: cup_wins
A2: career-most-wins | B2: career | C2: Most Career Wins | D2: player | E2: =INDEX('Player Stats'!$A$5:$A$12,MATCH(MAX('Player Stats'!$E$5:$E$12),'Player Stats'!$E$5:$E$12,0)) -> navy-steven | G2: =INDEX('Player Stats'!$B$5:$B$12,MATCH(MAX('Player Stats'!$E$5:$E$12),'Player Stats'!$E$5:$E$12,0)) -> Steve Wells | H2: =MAX('Player Stats'!$E$5:$E$12) -> 10 | I2: =TEXT(H2,"0")&" wins" -> 10 wins | K2: Player with the most career match wins. | L2: 10 | N2: ='Player Stats'!B5 -> Sam Griffiths | O2: =COUNTIF('Feed - Tournaments'!$O$2:$O$7,N2) -> 0
A3: career-best-points-pct | B3: career | C3: Best Career Points Percentage | D3: player | E3: =INDEX('Player Stats'!$A$5:$A$12,MATCH(MAX('Player Stats'!$I$5:$I$12),'Player Stats'!$I$5:$I$12,0)) -> navy-steven | G3: =INDEX('Player Stats'!$B$5:$B$12,MATCH(MAX('Player Stats'!$I$5:$I$12),'Player Stats'!$I$5:$I$12,0)) -> Steve Wells | H3: =MAX('Player Stats'!$I$5:$I$12) -> 0.66666667 | I3: =TEXT(H3,"0.0%")&"" -> 66.7% | K3: Player with the highest career points percentage. | L3: 20 | N3: ='Player Stats'!B6 -> Kevin Catliff | O3: =COUNTIF('Feed - Tournaments'!$O$2:$O$7,N3) -> 1
A4: career-most-losses | B4: career | C4: Most Career Losses | D4: player | E4: =INDEX('Player Stats'!$A$5:$A$12,MATCH(MAX('Player Stats'!$F$5:$F$12),'Player Stats'!$F$5:$F$12,0)) -> red-dylan | G4: =INDEX('Player Stats'!$B$5:$B$12,MATCH(MAX('Player Stats'!$F$5:$F$12),'Player Stats'!$F$5:$F$12,0)) -> Dylan Bradley | H4: =MAX('Player Stats'!$F$5:$F$12) -> 11 | I4: =TEXT(H4,"0")&" losses" -> 11 losses | K4: Player with the most career match losses. | L4: 30 | N4: ='Player Stats'!B7 -> Sean Bromley | O4: =COUNTIF('Feed - Tournaments'!$O$2:$O$7,N4) -> 0
A5: career-most-ties | B5: career | C5: Most Career Ties | D5: player | E5: =INDEX('Player Stats'!$A$5:$A$12,MATCH(MAX('Player Stats'!$G$5:$G$12),'Player Stats'!$G$5:$G$12,0)) -> navy-jj | G5: =INDEX('Player Stats'!$B$5:$B$12,MATCH(MAX('Player Stats'!$G$5:$G$12),'Player Stats'!$G$5:$G$12,0)) -> JJ Meakings | H5: =MAX('Player Stats'!$G$5:$G$12) -> 2 | I5: =TEXT(H5,"0")&" ties" -> 2 ties | K5: Player with the most career tied matches. | L5: 40 | N5: ='Player Stats'!B8 -> Dylan Bradley | O5: =COUNTIF('Feed - Tournaments'!$O$2:$O$7,N5) -> 1
A6: team-most-titles | B6: team | C6: Most Cyder Cup Titles | D6: team | F6: =IF(COUNTIF('Feed - Tournaments'!$K$2:$K$7,"navy")>=COUNTIF('Feed - Tournaments'!$K$2:$K$7,"red"),"navy","red") -> navy | G6: =PROPER(F6) -> Navy | H6: =MAX(COUNTIF('Feed - Tournaments'!$K$2:$K$7,"navy"),COUNTIF('Feed - Tournaments'!$K$2:$K$7,"red")) -> 3 | I6: =TEXT(H6,"0")&" titles" -> 3 titles | K6: Team with the most completed Cyder Cup victories. | L6: 50 | N6: ='Player Stats'!B9 -> Eric Bleim | O6: =COUNTIF('Feed - Tournaments'!$O$2:$O$7,N6) -> 2
A7: captain-most-wins | B7: captain | C7: Most Captain Victories | D7: player | E7: =INDEX('Player Stats'!$A$5:$A$12,MATCH(MAX($O$2:$O$9),$O$2:$O$9,0)) -> navy-eric | G7: =INDEX($N$2:$N$9,MATCH(MAX($O$2:$O$9),$O$2:$O$9,0)) -> Eric Bleim | H7: =MAX($O$2:$O$9) -> 2 | I7: =TEXT(H7,"0")&" captain victories" -> 2 captain victories | K7: Captain with the most Cyder Cup victories. | L7: 60 | N7: ='Player Stats'!B10 -> George Collister | O7: =COUNTIF('Feed - Tournaments'!$O$2:$O$7,N7) -> 0
A8: singles-most-wins | B8: format | C8: Most Singles Wins | D8: player | E8: =INDEX($N$13:$N$20,MATCH(MAX($Q$13:$Q$20),$Q$13:$Q$20,0)) -> red-sam | F8: =INDEX($P$13:$P$20,MATCH(MAX($Q$13:$Q$20),$Q$13:$Q$20,0)) -> red | G8: =INDEX($O$13:$O$20,MATCH(MAX($Q$13:$Q$20),$Q$13:$Q$20,0)) -> Sam Griffiths | H8: =MAX($Q$13:$Q$20) -> 3 | I8: =TEXT(H8,"0")&" wins" -> 3 wins | K8: Player with the most historical singles wins. | L8: 70 | N8: ='Player Stats'!B11 -> Steve Wells | O8: =COUNTIF('Feed - Tournaments'!$O$2:$O$7,N8) -> 0
A9: singles-best-pct | B9: format | C9: Best Singles Win Percentage | D9: player | E9: =INDEX($N$13:$N$20,MATCH(MAX($T$13:$T$20),$T$13:$T$20,0)) -> red-sam | F9: =INDEX($P$13:$P$20,MATCH(MAX($T$13:$T$20),$T$13:$T$20,0)) -> red | G9: =INDEX($O$13:$O$20,MATCH(MAX($T$13:$T$20),$T$13:$T$20,0)) -> Sam Griffiths | H9: =MAX($T$13:$T$20) -> 0.7 | I9: =TEXT(H9,"0.0%")&"" -> 70.0% | K9: Player with the best singles points percentage. | L9: 80 | N9: ='Player Stats'!B12 -> JJ Meakings | O9: =COUNTIF('Feed - Tournaments'!$O$2:$O$7,N9) -> 1
A10: fourball-most-wins | B10: format | C10: Most Fourball Wins | D10: player | E10: =INDEX($N$13:$N$20,MATCH(MAX($U$13:$U$20),$U$13:$U$20,0)) -> red-sam | F10: =INDEX($P$13:$P$20,MATCH(MAX($U$13:$U$20),$U$13:$U$20,0)) -> red | G10: =INDEX($O$13:$O$20,MATCH(MAX($U$13:$U$20),$U$13:$U$20,0)) -> Sam Griffiths | H10: =MAX($U$13:$U$20) -> 3 | I10: =TEXT(H10,"0")&" wins" -> 3 wins | K10: Player with the most historical fourball wins. | L10: 90
A11: fourball-best-pct | B11: format | C11: Best Fourball Win Percentage | D11: player | E11: =INDEX($N$13:$N$20,MATCH(MAX($X$13:$X$20),$X$13:$X$20,0)) -> red-sam | F11: =INDEX($P$13:$P$20,MATCH(MAX($X$13:$X$20),$X$13:$X$20,0)) -> red | G11: =INDEX($O$13:$O$20,MATCH(MAX($X$13:$X$20),$X$13:$X$20,0)) -> Sam Griffiths | H11: =MAX($X$13:$X$20) -> 0.6 | I11: =TEXT(H11,"0.0%")&"" -> 60.0% | K11: Player with the best fourball points percentage. | L11: 100
A12: scramble-most-wins | B12: format | C12: Most Scramble Wins | D12: player | E12: =INDEX($N$13:$N$20,MATCH(MAX($Y$13:$Y$20),$Y$13:$Y$20,0)) -> navy-steven | F12: =INDEX($P$13:$P$20,MATCH(MAX($Y$13:$Y$20),$Y$13:$Y$20,0)) -> navy | G12: =INDEX($O$13:$O$20,MATCH(MAX($Y$13:$Y$20),$Y$13:$Y$20,0)) -> Steve Wells | H12: =MAX($Y$13:$Y$20) -> 3 | I12: =TEXT(H12,"0")&" wins" -> 3 wins | K12: Player with the most historical scramble wins. | L12: 110 | N12: player_id | O12: player_name | P12: team_id | Q12: singles_w | R12: singles_l | S12: singles_t | T12: singles_pct | U12: fourball_w | V12: fourball_l | W12: fourball_t | X12: fourball_pct | Y12: scramble_w | Z12: scramble_l | AA12: scramble_t | AB12: scramble_pct
A13: scramble-best-pct | B13: format | C13: Best Scramble Win Percentage | D13: player | E13: =INDEX($N$13:$N$20,MATCH(MAX($AB$13:$AB$20),$AB$13:$AB$20,0)) -> navy-steven | F13: =INDEX($P$13:$P$20,MATCH(MAX($AB$13:$AB$20),$AB$13:$AB$20,0)) -> navy | G13: =INDEX($O$13:$O$20,MATCH(MAX($AB$13:$AB$20),$AB$13:$AB$20,0)) -> Steve Wells | H13: =MAX($AB$13:$AB$20) -> 0.75 | I13: =TEXT(H13,"0.0%")&"" -> 75.0% | K13: Player with the best scramble points percentage. | L13: 120 | N13: ='Player Stats'!A5 -> red-sam | O13: ='Player Stats'!B5 -> Sam Griffiths | P13: =LOWER('Player Stats'!C5) -> red | Q13: =COUNTIFS('Record Book'!$C$29:$C$196,"Singles",'Record Book'!$E$29:$E$196,$O13,'Record Book'!$I$29:$I$196,"W") -> 3 | R13: =COUNTIFS('Record Book'!$C$29:$C$196,"Singles",'Record Book'!$E$29:$E$196,$O13,'Record Book'!$I$29:$I$196,"L") -> 1 | S13: =COUNTIFS('Record Book'!$C$29:$C$196,"Singles",'Record Book'!$E$29:$E$196,$O13,'Record Book'!$I$29:$I$196,"T") -> 1 | T13: =IF(SUM(Q13:S13)=0,0,(Q13+0.5*S13)/SUM(Q13:S13)) -> 0.7 | U13: =COUNTIFS('Record Book'!$C$29:$C$196,"Fourball",'Record Book'!$E$29:$E$196,$O13,'Record Book'!$I$29:$I$196,"W") -> 3 | V13: =COUNTIFS('Record Book'!$C$29:$C$196,"Fourball",'Record Book'!$E$29:$E$196,$O13,'Record Book'!$I$29:$I$196,"L") -> 2 | W13: =COUNTIFS('Record Book'!$C$29:$C$196,"Fourball",'Record Book'!$E$29:$E$196,$O13,'Record Book'!$I$29:$I$196,"T") -> 0 | X13: =IF(SUM(U13:W13)=0,0,(U13+0.5*W13)/SUM(U13:W13)) -> 0.6 | Y13: =COUNTIFS('Record Book'!$C$29:$C$196,"Scramble",'Record Book'!$E$29:$E$196,$O13,'Record Book'!$I$29:$I$196,"W") -> 2 | Z13: =COUNTIFS('Record Book'!$C$29:$C$196,"Scramble",'Record Book'!$E$29:$E$196,$O13,'Record Book'!$I$29:$I$196,"L") -> 2 | AA13: =COUNTIFS('Record Book'!$C$29:$C$196,"Scramble",'Record Book'!$E$29:$E$196,$O13,'Record Book'!$I$29:$I$196,"T") -> 0 | AB13: =IF(SUM(Y13:AA13)=0,0,(Y13+0.5*AA13)/SUM(Y13:AA13)) -> 0.5
N14: ='Player Stats'!A6 -> red-kevin | O14: ='Player Stats'!B6 -> Kevin Catliff | P14: =LOWER('Player Stats'!C6) -> red | Q14: =COUNTIFS('Record Book'!$C$29:$C$196,"Singles",'Record Book'!$E$29:$E$196,$O14,'Record Book'!$I$29:$I$196,"W") -> 3 | R14: =COUNTIFS('Record Book'!$C$29:$C$196,"Singles",'Record Book'!$E$29:$E$196,$O14,'Record Book'!$I$29:$I$196,"L") -> 1 | S14: =COUNTIFS('Record Book'!$C$29:$C$196,"Singles",'Record Book'!$E$29:$E$196,$O14,'Record Book'!$I$29:$I$196,"T") -> 1 | T14: =IF(SUM(Q14:S14)=0,0,(Q14+0.5*S14)/SUM(Q14:S14)) -> 0.7 | U14: =COUNTIFS('Record Book'!$C$29:$C$196,"Fourball",'Record Book'!$E$29:$E$196,$O14,'Record Book'!$I$29:$I$196,"W") -> 1 | V14: =COUNTIFS('Record Book'!$C$29:$C$196,"Fourball",'Record Book'!$E$29:$E$196,$O14,'Record Book'!$I$29:$I$196,"L") -> 4 | W14: =COUNTIFS('Record Book'!$C$29:$C$196,"Fourball",'Record Book'!$E$29:$E$196,$O14,'Record Book'!$I$29:$I$196,"T") -> 0 | X14: =IF(SUM(U14:W14)=0,0,(U14+0.5*W14)/SUM(U14:W14)) -> 0.2 | Y14: =COUNTIFS('Record Book'!$C$29:$C$196,"Scramble",'Record Book'!$E$29:$E$196,$O14,'Record Book'!$I$29:$I$196,"W") -> 2 | Z14: =COUNTIFS('Record Book'!$C$29:$C$196,"Scramble",'Record Book'!$E$29:$E$196,$O14,'Record Book'!$I$29:$I$196,"L") -> 2 | AA14: =COUNTIFS('Record Book'!$C$29:$C$196,"Scramble",'Record Book'!$E$29:$E$196,$O14,'Record Book'!$I$29:$I$196,"T") -> 0 | AB14: =IF(SUM(Y14:AA14)=0,0,(Y14+0.5*AA14)/SUM(Y14:AA14)) -> 0.5
N15: ='Player Stats'!A7 -> red-sean | O15: ='Player Stats'!B7 -> Sean Bromley | P15: =LOWER('Player Stats'!C7) -> red | Q15: =COUNTIFS('Record Book'!$C$29:$C$196,"Singles",'Record Book'!$E$29:$E$196,$O15,'Record Book'!$I$29:$I$196,"W") -> 1 | R15: =COUNTIFS('Record Book'!$C$29:$C$196,"Singles",'Record Book'!$E$29:$E$196,$O15,'Record Book'!$I$29:$I$196,"L") -> 4 | S15: =COUNTIFS('Record Book'!$C$29:$C$196,"Singles",'Record Book'!$E$29:$E$196,$O15,'Record Book'!$I$29:$I$196,"T") -> 0 | T15: =IF(SUM(Q15:S15)=0,0,(Q15+0.5*S15)/SUM(Q15:S15)) -> 0.2 | U15: =COUNTIFS('Record Book'!$C$29:$C$196,"Fourball",'Record Book'!$E$29:$E$196,$O15,'Record Book'!$I$29:$I$196,"W") -> 2 | V15: =COUNTIFS('Record Book'!$C$29:$C$196,"Fourball",'Record Book'!$E$29:$E$196,$O15,'Record Book'!$I$29:$I$196,"L") -> 3 | W15: =COUNTIFS('Record Book'!$C$29:$C$196,"Fourball",'Record Book'!$E$29:$E$196,$O15,'Record Book'!$I$29:$I$196,"T") -> 0 | X15: =IF(SUM(U15:W15)=0,0,(U15+0.5*W15)/SUM(U15:W15)) -> 0.4 | Y15: =COUNTIFS('Record Book'!$C$29:$C$196,"Scramble",'Record Book'!$E$29:$E$196,$O15,'Record Book'!$I$29:$I$196,"W") -> 2 | Z15: =COUNTIFS('Record Book'!$C$29:$C$196,"Scramble",'Record Book'!$E$29:$E$196,$O15,'Record Book'!$I$29:$I$196,"L") -> 2 | AA15: =COUNTIFS('Record Book'!$C$29:$C$196,"Scramble",'Record Book'!$E$29:$E$196,$O15,'Record Book'!$I$29:$I$196,"T") -> 0 | AB15: =IF(SUM(Y15:AA15)=0,0,(Y15+0.5*AA15)/SUM(Y15:AA15)) -> 0.5
N16: ='Player Stats'!A8 -> red-dylan | O16: ='Player Stats'!B8 -> Dylan Bradley | P16: =LOWER('Player Stats'!C8) -> red | Q16: =COUNTIFS('Record Book'!$C$29:$C$196,"Singles",'Record Book'!$E$29:$E$196,$O16,'Record Book'!$I$29:$I$196,"W") -> 2 | R16: =COUNTIFS('Record Book'!$C$29:$C$196,"Singles",'Record Book'!$E$29:$E$196,$O16,'Record Book'!$I$29:$I$196,"L") -> 3 | S16: =COUNTIFS('Record Book'!$C$29:$C$196,"Singles",'Record Book'!$E$29:$E$196,$O16,'Record Book'!$I$29:$I$196,"T") -> 0 | T16: =IF(SUM(Q16:S16)=0,0,(Q16+0.5*S16)/SUM(Q16:S16)) -> 0.4 | U16: =COUNTIFS('Record Book'!$C$29:$C$196,"Fourball",'Record Book'!$E$29:$E$196,$O16,'Record Book'!$I$29:$I$196,"W") -> 2 | V16: =COUNTIFS('Record Book'!$C$29:$C$196,"Fourball",'Record Book'!$E$29:$E$196,$O16,'Record Book'!$I$29:$I$196,"L") -> 3 | W16: =COUNTIFS('Record Book'!$C$29:$C$196,"Fourball",'Record Book'!$E$29:$E$196,$O16,'Record Book'!$I$29:$I$196,"T") -> 0 | X16: =IF(SUM(U16:W16)=0,0,(U16+0.5*W16)/SUM(U16:W16)) -> 0.4 | Y16: =COUNTIFS('Record Book'!$C$29:$C$196,"Scramble",'Record Book'!$E$29:$E$196,$O16,'Record Book'!$I$29:$I$196,"W") -> 0 | Z16: =COUNTIFS('Record Book'!$C$29:$C$196,"Scramble",'Record Book'!$E$29:$E$196,$O16,'Record Book'!$I$29:$I$196,"L") -> 4 | AA16: =COUNTIFS('Record Book'!$C$29:$C$196,"Scramble",'Record Book'!$E$29:$E$196,$O16,'Record Book'!$I$29:$I$196,"T") -> 0 | AB16: =IF(SUM(Y16:AA16)=0,0,(Y16+0.5*AA16)/SUM(Y16:AA16)) -> 0
